Unhandled exception in thread started by <function check_errors.<locals>.wrapper at 0x03EA9300>
Traceback (most recent call last):
  File "C:\Users\siddhant\AppData\Local\Programs\Python\Python36-32\lib\site-packages\django\utils\autoreload.py", line 225, in wrapper
    fn(*args, **kwargs)
  File "C:\Users\siddhant\AppData\Local\Programs\Python\Python36-32\lib\site-packages\django\core\management\commands\runserver.py", line 109, in inner_run
    autoreload.raise_last_exception()
  File "C:\Users\siddhant\AppData\Local\Programs\Python\Python36-32\lib\site-packages\django\utils\autoreload.py", line 248, in raise_last_exception
    raise _exception[1]
  File "C:\Users\siddhant\AppData\Local\Programs\Python\Python36-32\lib\site-packages\django\core\management\__init__.py", line 337, in execute
    autoreload.check_errors(django.setup)()
  File "C:\Users\siddhant\AppData\Local\Programs\Python\Python36-32\lib\site-packages\django\utils\autoreload.py", line 225, in wrapper
    fn(*args, **kwargs)
  File "C:\Users\siddhant\AppData\Local\Programs\Python\Python36-32\lib\site-packages\django\__init__.py", line 24, in setup
    apps.populate(settings.INSTALLED_APPS)
  File "C:\Users\siddhant\AppData\Local\Programs\Python\Python36-32\lib\site-packages\django\apps\registry.py", line 89, in populate
    app_config = AppConfig.create(entry)
  File "C:\Users\siddhant\AppData\Local\Programs\Python\Python36-32\lib\site-packages\django\apps\config.py", line 90, in create
    module = import_module(entry)
  File "C:\Users\siddhant\AppData\Local\Programs\Python\Python36-32\lib\importlib\__init__.py", line 126, in import_module
    return _bootstrap._gcd_import(name[level:], package, level)
  File "<frozen importlib._bootstrap>", line 994, in _gcd_import
  File "<frozen importlib._bootstrap>", line 971, in _find_and_load
  File "<frozen importlib._bootstrap>", line 953, in _find_and_load_unlocked
ModuleNotFoundError: No module named 'corsheaders'
Unhandled exception in thread started by <function check_errors.<locals>.wrapper at 0x03CF1300>
Traceback (most recent call last):
  File "C:\Users\siddhant\AppData\Local\Programs\Python\Python36-32\lib\site-packages\django\utils\autoreload.py", line 225, in wrapper
    fn(*args, **kwargs)
  File "C:\Users\siddhant\AppData\Local\Programs\Python\Python36-32\lib\site-packages\django\core\management\commands\runserver.py", line 109, in inner_run
    autoreload.raise_last_exception()
  File "C:\Users\siddhant\AppData\Local\Programs\Python\Python36-32\lib\site-packages\django\utils\autoreload.py", line 248, in raise_last_exception
    raise _exception[1]
  File "C:\Users\siddhant\AppData\Local\Programs\Python\Python36-32\lib\site-packages\django\core\management\__init__.py", line 337, in execute
    autoreload.check_errors(django.setup)()
  File "C:\Users\siddhant\AppData\Local\Programs\Python\Python36-32\lib\site-packages\django\utils\autoreload.py", line 225, in wrapper
    fn(*args, **kwargs)
  File "C:\Users\siddhant\AppData\Local\Programs\Python\Python36-32\lib\site-packages\django\__init__.py", line 24, in setup
    apps.populate(settings.INSTALLED_APPS)
  File "C:\Users\siddhant\AppData\Local\Programs\Python\Python36-32\lib\site-packages\django\apps\registry.py", line 89, in populate
    app_config = AppConfig.create(entry)
  File "C:\Users\siddhant\AppData\Local\Programs\Python\Python36-32\lib\site-packages\django\apps\config.py", line 90, in create
    module = import_module(entry)
  File "C:\Users\siddhant\AppData\Local\Programs\Python\Python36-32\lib\importlib\__init__.py", line 126, in import_module
    return _bootstrap._gcd_import(name[level:], package, level)
  File "<frozen importlib._bootstrap>", line 994, in _gcd_import
  File "<frozen importlib._bootstrap>", line 971, in _find_and_load
  File "<frozen importlib._bootstrap>", line 953, in _find_and_load_unlocked
ModuleNotFoundError: No module named 'corsheaders'
Unhandled exception in thread started by <function check_errors.<locals>.wrapper at 0x035E1300>
Traceback (most recent call last):
  File "C:\Users\siddhant\AppData\Local\Programs\Python\Python36-32\lib\site-packages\django\utils\autoreload.py", line 225, in wrapper
    fn(*args, **kwargs)
  File "C:\Users\siddhant\AppData\Local\Programs\Python\Python36-32\lib\site-packages\django\core\management\commands\runserver.py", line 109, in inner_run
    autoreload.raise_last_exception()
  File "C:\Users\siddhant\AppData\Local\Programs\Python\Python36-32\lib\site-packages\django\utils\autoreload.py", line 248, in raise_last_exception
    raise _exception[1]
  File "C:\Users\siddhant\AppData\Local\Programs\Python\Python36-32\lib\site-packages\django\core\management\__init__.py", line 337, in execute
    autoreload.check_errors(django.setup)()
  File "C:\Users\siddhant\AppData\Local\Programs\Python\Python36-32\lib\site-packages\django\utils\autoreload.py", line 225, in wrapper
    fn(*args, **kwargs)
  File "C:\Users\siddhant\AppData\Local\Programs\Python\Python36-32\lib\site-packages\django\__init__.py", line 24, in setup
    apps.populate(settings.INSTALLED_APPS)
  File "C:\Users\siddhant\AppData\Local\Programs\Python\Python36-32\lib\site-packages\django\apps\registry.py", line 89, in populate
    app_config = AppConfig.create(entry)
  File "C:\Users\siddhant\AppData\Local\Programs\Python\Python36-32\lib\site-packages\django\apps\config.py", line 90, in create
    module = import_module(entry)
  File "C:\Users\siddhant\AppData\Local\Programs\Python\Python36-32\lib\importlib\__init__.py", line 126, in import_module
    return _bootstrap._gcd_import(name[level:], package, level)
  File "<frozen importlib._bootstrap>", line 994, in _gcd_import
  File "<frozen importlib._bootstrap>", line 971, in _find_and_load
  File "<frozen importlib._bootstrap>", line 953, in _find_and_load_unlocked
ModuleNotFoundError: No module named 'corsheaders'
[20/Oct/2018 15:54:07] "GET /api/ HTTP/1.1" 200 5370
[20/Oct/2018 15:54:07] "GET /static/rest_framework/css/bootstrap.min.css HTTP/1.1" 200 121200
[20/Oct/2018 15:54:07] "GET /static/rest_framework/css/prettify.css HTTP/1.1" 200 817
[20/Oct/2018 15:54:07] "GET /static/rest_framework/js/ajax-form.js HTTP/1.1" 200 3597
[20/Oct/2018 15:54:07] "GET /static/rest_framework/js/jquery-3.3.1.min.js HTTP/1.1" 200 86927
[20/Oct/2018 15:54:07] "GET /static/rest_framework/js/bootstrap.min.js HTTP/1.1" 200 37045
[20/Oct/2018 15:54:07] "GET /static/rest_framework/js/prettify-min.js HTTP/1.1" 200 13632
[20/Oct/2018 15:54:07] "GET /static/rest_framework/js/csrf.js HTTP/1.1" 200 1735
[20/Oct/2018 15:54:08] "GET /static/rest_framework/js/default.js HTTP/1.1" 200 1262
[20/Oct/2018 15:54:08] "GET /static/rest_framework/css/default.css HTTP/1.1" 200 1131
[20/Oct/2018 15:54:08] "GET /static/rest_framework/css/bootstrap-tweaks.css HTTP/1.1" 200 3385
[20/Oct/2018 15:54:08] "GET /static/rest_framework/img/grid.png HTTP/1.1" 200 1458
[20/Oct/2018 15:54:11] "GET /favicon.ico HTTP/1.1" 200 2116
Performing system checks...

System check identified no issues (0 silenced).

You have 2 unapplied migration(s). Your project may not work properly until you apply the migrations for app(s): api.
Run 'python manage.py migrate' to apply them.
October 20, 2018 - 15:54:06
Django version 2.1.1, using settings 'steps.settings'
Starting development server at http://0.0.0.0:8000/
Quit the server with CTRL-BREAK.
[20/Oct/2018 15:58:44] "GET /api/sidewalk/ HTTP/1.1" 200 4946
[20/Oct/2018 15:58:47] "GET /favicon.ico HTTP/1.1" 200 2116
[20/Oct/2018 16:02:38] "GET /api/sidewalk/ HTTP/1.1" 200 4946
[20/Oct/2018 16:02:40] "GET /favicon.ico HTTP/1.1" 200 2116
[20/Oct/2018 16:02:42] "GET /api/sidewalk/ HTTP/1.1" 200 4946
[20/Oct/2018 16:02:43] "GET /favicon.ico HTTP/1.1" 200 2116
[20/Oct/2018 16:02:43] "GET /api/sidewalk/ HTTP/1.1" 200 4946
[20/Oct/2018 16:02:44] "GET /favicon.ico HTTP/1.1" 200 2116
[20/Oct/2018 16:02:45] "GET /favicon.ico HTTP/1.1" 200 2116
[20/Oct/2018 16:02:46] "GET /api/ HTTP/1.1" 200 5370
[20/Oct/2018 16:02:46] "GET /favicon.ico HTTP/1.1" 200 2116
[20/Oct/2018 16:02:49] "GET /api/sidewalk/ HTTP/1.1" 200 4946
[20/Oct/2018 16:02:50] "GET /favicon.ico HTTP/1.1" 200 2116
Performing system checks...

System check identified no issues (0 silenced).
October 20, 2018 - 15:56:04
Django version 2.1.1, using settings 'steps.settings'
Starting development server at http://0.0.0.0:8000/
Quit the server with CTRL-BREAK.
[20/Oct/2018 16:03:27] "GET /api/sidewalk/ HTTP/1.1" 200 4985
[20/Oct/2018 16:03:28] "GET /favicon.ico HTTP/1.1" 200 2116
Performing system checks...

System check identified no issues (0 silenced).
October 20, 2018 - 16:03:27
Django version 2.1.1, using settings 'steps.settings'
Starting development server at http://0.0.0.0:8000/
Quit the server with CTRL-BREAK.
Performing system checks...

System check identified no issues (0 silenced).
October 20, 2018 - 16:05:42
Django version 2.1.1, using settings 'steps.settings'
Starting development server at http://0.0.0.0:8000/
Quit the server with CTRL-BREAK.
Unhandled exception in thread started by <function check_errors.<locals>.wrapper at 0x032AB0C0>
Traceback (most recent call last):
  File "C:\Users\siddhant\AppData\Local\Programs\Python\Python36-32\lib\site-packages\django\utils\autoreload.py", line 225, in wrapper
    fn(*args, **kwargs)
  File "C:\Users\siddhant\AppData\Local\Programs\Python\Python36-32\lib\site-packages\django\core\management\commands\runserver.py", line 117, in inner_run
    self.check(display_num_errors=True)
  File "C:\Users\siddhant\AppData\Local\Programs\Python\Python36-32\lib\site-packages\django\core\management\base.py", line 379, in check
    include_deployment_checks=include_deployment_checks,
  File "C:\Users\siddhant\AppData\Local\Programs\Python\Python36-32\lib\site-packages\django\core\management\base.py", line 366, in _run_checks
    return checks.run_checks(**kwargs)
  File "C:\Users\siddhant\AppData\Local\Programs\Python\Python36-32\lib\site-packages\django\core\checks\registry.py", line 71, in run_checks
    new_errors = check(app_configs=app_configs)
  File "C:\Users\siddhant\AppData\Local\Programs\Python\Python36-32\lib\site-packages\django\core\checks\urls.py", line 40, in check_url_namespaces_unique
    all_namespaces = _load_all_namespaces(resolver)
  File "C:\Users\siddhant\AppData\Local\Programs\Python\Python36-32\lib\site-packages\django\core\checks\urls.py", line 57, in _load_all_namespaces
    url_patterns = getattr(resolver, 'url_patterns', [])
  File "C:\Users\siddhant\AppData\Local\Programs\Python\Python36-32\lib\site-packages\django\utils\functional.py", line 37, in __get__
    res = instance.__dict__[self.name] = self.func(instance)
  File "C:\Users\siddhant\AppData\Local\Programs\Python\Python36-32\lib\site-packages\django\urls\resolvers.py", line 533, in url_patterns
    patterns = getattr(self.urlconf_module, "urlpatterns", self.urlconf_module)
  File "C:\Users\siddhant\AppData\Local\Programs\Python\Python36-32\lib\site-packages\django\utils\functional.py", line 37, in __get__
    res = instance.__dict__[self.name] = self.func(instance)
  File "C:\Users\siddhant\AppData\Local\Programs\Python\Python36-32\lib\site-packages\django\urls\resolvers.py", line 526, in urlconf_module
    return import_module(self.urlconf_name)
  File "C:\Users\siddhant\AppData\Local\Programs\Python\Python36-32\lib\importlib\__init__.py", line 126, in import_module
    return _bootstrap._gcd_import(name[level:], package, level)
  File "<frozen importlib._bootstrap>", line 994, in _gcd_import
  File "<frozen importlib._bootstrap>", line 971, in _find_and_load
  File "<frozen importlib._bootstrap>", line 955, in _find_and_load_unlocked
  File "<frozen importlib._bootstrap>", line 665, in _load_unlocked
  File "<frozen importlib._bootstrap_external>", line 678, in exec_module
  File "<frozen importlib._bootstrap>", line 219, in _call_with_frames_removed
  File "C:\Users\siddhant\Desktop\steps\django_steps\steps\urls.py", line 23, in <module>
    path('api/', include('api.urls')),
  File "C:\Users\siddhant\AppData\Local\Programs\Python\Python36-32\lib\site-packages\django\urls\conf.py", line 34, in include
    urlconf_module = import_module(urlconf_module)
  File "C:\Users\siddhant\AppData\Local\Programs\Python\Python36-32\lib\importlib\__init__.py", line 126, in import_module
    return _bootstrap._gcd_import(name[level:], package, level)
  File "<frozen importlib._bootstrap>", line 994, in _gcd_import
  File "<frozen importlib._bootstrap>", line 971, in _find_and_load
  File "<frozen importlib._bootstrap>", line 955, in _find_and_load_unlocked
  File "<frozen importlib._bootstrap>", line 665, in _load_unlocked
  File "<frozen importlib._bootstrap_external>", line 678, in exec_module
  File "<frozen importlib._bootstrap>", line 219, in _call_with_frames_removed
  File "C:\Users\siddhant\Desktop\steps\django_steps\api\urls.py", line 2, in <module>
    from . import views
  File "C:\Users\siddhant\Desktop\steps\django_steps\api\views.py", line 4, in <module>
    from .serializers import SidewalkSerializer, SidewalkRatingsSerializer
  File "C:\Users\siddhant\Desktop\steps\django_steps\api\serializers.py", line 13
    fields = '__all__'
                     ^
IndentationError: unindent does not match any outer indentation level
Performing system checks...

Performing system checks...

System check identified no issues (0 silenced).
October 20, 2018 - 16:08:03
Django version 2.1.1, using settings 'steps.settings'
Starting development server at http://0.0.0.0:8000/
Quit the server with CTRL-BREAK.
[20/Oct/2018 16:09:26] "GET /api/sidewalkRating/ HTTP/1.1" 200 5422
[20/Oct/2018 16:09:28] "GET /favicon.ico HTTP/1.1" 200 2116
[20/Oct/2018 16:09:43] "GET /api/sidewalkRating/ HTTP/1.1" 200 5422
[20/Oct/2018 16:09:44] "GET /favicon.ico HTTP/1.1" 200 2116
[20/Oct/2018 16:09:56] "GET /api// HTTP/1.1" 200 2116
[20/Oct/2018 16:09:58] "GET /api/ HTTP/1.1" 200 5370
[20/Oct/2018 16:09:59] "GET /favicon.ico HTTP/1.1" 200 2116
[20/Oct/2018 16:10:03] "GET /api/sidewalkRating/ HTTP/1.1" 200 5422
[20/Oct/2018 16:10:03] "GET /favicon.ico HTTP/1.1" 200 2116
[20/Oct/2018 16:10:06] "GET /favicon.ico HTTP/1.1" 200 2116
[20/Oct/2018 16:10:08] "GET /api/sidewalk/ HTTP/1.1" 200 4985
[20/Oct/2018 16:10:08] "GET /favicon.ico HTTP/1.1" 200 2116
[20/Oct/2018 16:10:10] "GET /favicon.ico HTTP/1.1" 200 2116
[20/Oct/2018 16:10:16] "GET /api/sidewalkRating/ HTTP/1.1" 200 5422
[20/Oct/2018 16:10:17] "GET /favicon.ico HTTP/1.1" 200 2116
Performing system checks...

System check identified no issues (0 silenced).
October 20, 2018 - 16:09:21
Django version 2.1.1, using settings 'steps.settings'
Starting development server at http://0.0.0.0:8000/
Quit the server with CTRL-BREAK.
Performing system checks...

System check identified no issues (0 silenced).
October 20, 2018 - 16:11:09
Django version 2.1.1, using settings 'steps.settings'
Starting development server at http://0.0.0.0:8000/
Quit the server with CTRL-BREAK.
Performing system checks...

System check identified no issues (0 silenced).
October 20, 2018 - 16:14:14
Django version 2.1.1, using settings 'steps.settings'
Starting development server at http://0.0.0.0:8000/
Quit the server with CTRL-BREAK.
Performing system checks...

System check identified no issues (0 silenced).
October 20, 2018 - 16:14:33
Django version 2.1.1, using settings 'steps.settings'
Starting development server at http://0.0.0.0:8000/
Quit the server with CTRL-BREAK.
[20/Oct/2018 16:15:18] "GET /api/sidewalkRating/ HTTP/1.1" 200 5419
[20/Oct/2018 16:15:22] "GET /favicon.ico HTTP/1.1" 200 2116
[20/Oct/2018 16:15:22] "GET /api/sidewalk/ HTTP/1.1" 200 4985
[20/Oct/2018 16:15:23] "GET /favicon.ico HTTP/1.1" 200 2116
Performing system checks...

System check identified no issues (0 silenced).
October 20, 2018 - 16:14:52
Django version 2.1.1, using settings 'steps.settings'
Starting development server at http://0.0.0.0:8000/
Quit the server with CTRL-BREAK.
[20/Oct/2018 16:49:43] "GET /api/ HTTP/1.1" 200 5370
[20/Oct/2018 16:49:45] "GET /favicon.ico HTTP/1.1" 200 2116
Internal Server Error: /api/sidewalk/
Traceback (most recent call last):
  File "C:\Users\siddhant\AppData\Local\Programs\Python\Python36-32\lib\site-packages\django\db\backends\utils.py", line 85, in _execute
    return self.cursor.execute(sql, params)
  File "C:\Users\siddhant\AppData\Local\Programs\Python\Python36-32\lib\site-packages\django\db\backends\mysql\base.py", line 71, in execute
    return self.cursor.execute(query, args)
  File "C:\Users\siddhant\AppData\Local\Programs\Python\Python36-32\lib\site-packages\MySQLdb\cursors.py", line 250, in execute
    self.errorhandler(self, exc, value)
  File "C:\Users\siddhant\AppData\Local\Programs\Python\Python36-32\lib\site-packages\MySQLdb\connections.py", line 50, in defaulterrorhandler
    raise errorvalue
  File "C:\Users\siddhant\AppData\Local\Programs\Python\Python36-32\lib\site-packages\MySQLdb\cursors.py", line 247, in execute
    res = self._query(query)
  File "C:\Users\siddhant\AppData\Local\Programs\Python\Python36-32\lib\site-packages\MySQLdb\cursors.py", line 411, in _query
    rowcount = self._do_query(q)
  File "C:\Users\siddhant\AppData\Local\Programs\Python\Python36-32\lib\site-packages\MySQLdb\cursors.py", line 374, in _do_query
    db.query(q)
  File "C:\Users\siddhant\AppData\Local\Programs\Python\Python36-32\lib\site-packages\MySQLdb\connections.py", line 277, in query
    _mysql.connection.query(self, query)
_mysql_exceptions.OperationalError: (1065, 'Query was empty')

The above exception was the direct cause of the following exception:

Traceback (most recent call last):
  File "C:\Users\siddhant\AppData\Local\Programs\Python\Python36-32\lib\site-packages\django\core\handlers\exception.py", line 34, in inner
    response = get_response(request)
  File "C:\Users\siddhant\AppData\Local\Programs\Python\Python36-32\lib\site-packages\django\core\handlers\base.py", line 126, in _get_response
    response = self.process_exception_by_middleware(e, request)
  File "C:\Users\siddhant\AppData\Local\Programs\Python\Python36-32\lib\site-packages\django\core\handlers\base.py", line 124, in _get_response
    response = wrapped_callback(request, *callback_args, **callback_kwargs)
  File "C:\Users\siddhant\AppData\Local\Programs\Python\Python36-32\lib\site-packages\django\views\decorators\csrf.py", line 54, in wrapped_view
    return view_func(*args, **kwargs)
  File "C:\Users\siddhant\AppData\Local\Programs\Python\Python36-32\lib\site-packages\rest_framework\viewsets.py", line 103, in view
    return self.dispatch(request, *args, **kwargs)
  File "C:\Users\siddhant\AppData\Local\Programs\Python\Python36-32\lib\site-packages\rest_framework\views.py", line 483, in dispatch
    response = self.handle_exception(exc)
  File "C:\Users\siddhant\AppData\Local\Programs\Python\Python36-32\lib\site-packages\rest_framework\views.py", line 443, in handle_exception
    self.raise_uncaught_exception(exc)
  File "C:\Users\siddhant\AppData\Local\Programs\Python\Python36-32\lib\site-packages\rest_framework\views.py", line 480, in dispatch
    response = handler(request, *args, **kwargs)
  File "C:\Users\siddhant\AppData\Local\Programs\Python\Python36-32\lib\site-packages\rest_framework\mixins.py", line 48, in list
    return Response(serializer.data)
  File "C:\Users\siddhant\AppData\Local\Programs\Python\Python36-32\lib\site-packages\rest_framework\serializers.py", line 765, in data
    ret = super(ListSerializer, self).data
  File "C:\Users\siddhant\AppData\Local\Programs\Python\Python36-32\lib\site-packages\rest_framework\serializers.py", line 262, in data
    self._data = self.to_representation(self.instance)
  File "C:\Users\siddhant\AppData\Local\Programs\Python\Python36-32\lib\site-packages\rest_framework\serializers.py", line 683, in to_representation
    self.child.to_representation(item) for item in iterable
  File "C:\Users\siddhant\AppData\Local\Programs\Python\Python36-32\lib\site-packages\django\db\models\query.py", line 1339, in __iter__
    self._fetch_all()
  File "C:\Users\siddhant\AppData\Local\Programs\Python\Python36-32\lib\site-packages\django\db\models\query.py", line 1326, in _fetch_all
    self._result_cache = list(self.iterator())
  File "C:\Users\siddhant\AppData\Local\Programs\Python\Python36-32\lib\site-packages\django\db\models\query.py", line 1349, in iterator
    query = iter(self.query)
  File "C:\Users\siddhant\AppData\Local\Programs\Python\Python36-32\lib\site-packages\django\db\models\sql\query.py", line 96, in __iter__
    self._execute_query()
  File "C:\Users\siddhant\AppData\Local\Programs\Python\Python36-32\lib\site-packages\django\db\models\sql\query.py", line 130, in _execute_query
    self.cursor.execute(self.sql, params)
  File "C:\Users\siddhant\AppData\Local\Programs\Python\Python36-32\lib\site-packages\django\db\backends\utils.py", line 100, in execute
    return super().execute(sql, params)
  File "C:\Users\siddhant\AppData\Local\Programs\Python\Python36-32\lib\site-packages\django\db\backends\utils.py", line 68, in execute
    return self._execute_with_wrappers(sql, params, many=False, executor=self._execute)
  File "C:\Users\siddhant\AppData\Local\Programs\Python\Python36-32\lib\site-packages\django\db\backends\utils.py", line 77, in _execute_with_wrappers
    return executor(sql, params, many, context)
  File "C:\Users\siddhant\AppData\Local\Programs\Python\Python36-32\lib\site-packages\django\db\backends\utils.py", line 85, in _execute
    return self.cursor.execute(sql, params)
  File "C:\Users\siddhant\AppData\Local\Programs\Python\Python36-32\lib\site-packages\django\db\utils.py", line 89, in __exit__
    raise dj_exc_value.with_traceback(traceback) from exc_value
  File "C:\Users\siddhant\AppData\Local\Programs\Python\Python36-32\lib\site-packages\django\db\backends\utils.py", line 85, in _execute
    return self.cursor.execute(sql, params)
  File "C:\Users\siddhant\AppData\Local\Programs\Python\Python36-32\lib\site-packages\django\db\backends\mysql\base.py", line 71, in execute
    return self.cursor.execute(query, args)
  File "C:\Users\siddhant\AppData\Local\Programs\Python\Python36-32\lib\site-packages\MySQLdb\cursors.py", line 250, in execute
    self.errorhandler(self, exc, value)
  File "C:\Users\siddhant\AppData\Local\Programs\Python\Python36-32\lib\site-packages\MySQLdb\connections.py", line 50, in defaulterrorhandler
    raise errorvalue
  File "C:\Users\siddhant\AppData\Local\Programs\Python\Python36-32\lib\site-packages\MySQLdb\cursors.py", line 247, in execute
    res = self._query(query)
  File "C:\Users\siddhant\AppData\Local\Programs\Python\Python36-32\lib\site-packages\MySQLdb\cursors.py", line 411, in _query
    rowcount = self._do_query(q)
  File "C:\Users\siddhant\AppData\Local\Programs\Python\Python36-32\lib\site-packages\MySQLdb\cursors.py", line 374, in _do_query
    db.query(q)
  File "C:\Users\siddhant\AppData\Local\Programs\Python\Python36-32\lib\site-packages\MySQLdb\connections.py", line 277, in query
    _mysql.connection.query(self, query)
django.db.utils.OperationalError: (1065, 'Query was empty')
[20/Oct/2018 16:49:46] "GET /api/sidewalk/ HTTP/1.1" 500 212108
[20/Oct/2018 16:49:47] "GET /favicon.ico HTTP/1.1" 200 2116
Performing system checks...

System check identified no issues (0 silenced).
October 20, 2018 - 16:49:21
Django version 2.1.1, using settings 'steps.settings'
Starting development server at http://0.0.0.0:8000/
Quit the server with CTRL-BREAK.
[20/Oct/2018 16:50:02] "GET /api/sidewalk/ HTTP/1.1" 200 4985
[20/Oct/2018 16:50:03] "GET /favicon.ico HTTP/1.1" 200 2116
Performing system checks...

System check identified no issues (0 silenced).
October 20, 2018 - 16:50:01
Django version 2.1.1, using settings 'steps.settings'
Starting development server at http://0.0.0.0:8000/
Quit the server with CTRL-BREAK.
Performing system checks...

System check identified no issues (0 silenced).
October 20, 2018 - 16:51:36
Django version 2.1.1, using settings 'steps.settings'
Starting development server at http://0.0.0.0:8000/
Quit the server with CTRL-BREAK.
Performing system checks...

System check identified no issues (0 silenced).
October 20, 2018 - 16:53:12
Django version 2.1.1, using settings 'steps.settings'
Starting development server at http://0.0.0.0:8000/
Quit the server with CTRL-BREAK.
[20/Oct/2018 16:53:24] "GET /api/sidewalk/ HTTP/1.1" 200 4985
[20/Oct/2018 16:53:24] "GET /favicon.ico HTTP/1.1" 200 2116
Performing system checks...

System check identified no issues (0 silenced).
October 20, 2018 - 16:53:21
Django version 2.1.1, using settings 'steps.settings'
Starting development server at http://0.0.0.0:8000/
Quit the server with CTRL-BREAK.
Performing system checks...

System check identified no issues (0 silenced).
October 20, 2018 - 16:53:49
Django version 2.1.1, using settings 'steps.settings'
Starting development server at http://0.0.0.0:8000/
Quit the server with CTRL-BREAK.
[20/Oct/2018 16:54:21] "GET /api/sidewalk/ HTTP/1.1" 200 4985
[20/Oct/2018 16:54:22] "GET /favicon.ico HTTP/1.1" 200 2116
[20/Oct/2018 16:54:25] "GET /api/sidewalk/ HTTP/1.1" 200 4985
[20/Oct/2018 16:54:26] "GET /favicon.ico HTTP/1.1" 200 2116
Performing system checks...

System check identified no issues (0 silenced).
October 20, 2018 - 16:54:18
Django version 2.1.1, using settings 'steps.settings'
Starting development server at http://0.0.0.0:8000/
Quit the server with CTRL-BREAK.
Performing system checks...

System check identified no issues (0 silenced).
October 20, 2018 - 16:55:03
Django version 2.1.1, using settings 'steps.settings'
Starting development server at http://0.0.0.0:8000/
Quit the server with CTRL-BREAK.
Unhandled exception in thread started by <function check_errors.<locals>.wrapper at 0x03E1B0C0>
Traceback (most recent call last):
  File "C:\Users\siddhant\AppData\Local\Programs\Python\Python36-32\lib\site-packages\django\utils\autoreload.py", line 225, in wrapper
    fn(*args, **kwargs)
  File "C:\Users\siddhant\AppData\Local\Programs\Python\Python36-32\lib\site-packages\django\core\management\commands\runserver.py", line 117, in inner_run
    self.check(display_num_errors=True)
  File "C:\Users\siddhant\AppData\Local\Programs\Python\Python36-32\lib\site-packages\django\core\management\base.py", line 379, in check
    include_deployment_checks=include_deployment_checks,
  File "C:\Users\siddhant\AppData\Local\Programs\Python\Python36-32\lib\site-packages\django\core\management\base.py", line 366, in _run_checks
    return checks.run_checks(**kwargs)
  File "C:\Users\siddhant\AppData\Local\Programs\Python\Python36-32\lib\site-packages\django\core\checks\registry.py", line 71, in run_checks
    new_errors = check(app_configs=app_configs)
  File "C:\Users\siddhant\AppData\Local\Programs\Python\Python36-32\lib\site-packages\django\core\checks\urls.py", line 40, in check_url_namespaces_unique
    all_namespaces = _load_all_namespaces(resolver)
  File "C:\Users\siddhant\AppData\Local\Programs\Python\Python36-32\lib\site-packages\django\core\checks\urls.py", line 57, in _load_all_namespaces
    url_patterns = getattr(resolver, 'url_patterns', [])
  File "C:\Users\siddhant\AppData\Local\Programs\Python\Python36-32\lib\site-packages\django\utils\functional.py", line 37, in __get__
    res = instance.__dict__[self.name] = self.func(instance)
  File "C:\Users\siddhant\AppData\Local\Programs\Python\Python36-32\lib\site-packages\django\urls\resolvers.py", line 533, in url_patterns
    patterns = getattr(self.urlconf_module, "urlpatterns", self.urlconf_module)
  File "C:\Users\siddhant\AppData\Local\Programs\Python\Python36-32\lib\site-packages\django\utils\functional.py", line 37, in __get__
    res = instance.__dict__[self.name] = self.func(instance)
  File "C:\Users\siddhant\AppData\Local\Programs\Python\Python36-32\lib\site-packages\django\urls\resolvers.py", line 526, in urlconf_module
    return import_module(self.urlconf_name)
  File "C:\Users\siddhant\AppData\Local\Programs\Python\Python36-32\lib\importlib\__init__.py", line 126, in import_module
    return _bootstrap._gcd_import(name[level:], package, level)
  File "<frozen importlib._bootstrap>", line 994, in _gcd_import
  File "<frozen importlib._bootstrap>", line 971, in _find_and_load
  File "<frozen importlib._bootstrap>", line 955, in _find_and_load_unlocked
  File "<frozen importlib._bootstrap>", line 665, in _load_unlocked
  File "<frozen importlib._bootstrap_external>", line 678, in exec_module
  File "<frozen importlib._bootstrap>", line 219, in _call_with_frames_removed
  File "C:\Users\siddhant\Desktop\steps\django_steps\steps\urls.py", line 23, in <module>
    path('api/', include('api.urls')),
  File "C:\Users\siddhant\AppData\Local\Programs\Python\Python36-32\lib\site-packages\django\urls\conf.py", line 34, in include
    urlconf_module = import_module(urlconf_module)
  File "C:\Users\siddhant\AppData\Local\Programs\Python\Python36-32\lib\importlib\__init__.py", line 126, in import_module
    return _bootstrap._gcd_import(name[level:], package, level)
  File "<frozen importlib._bootstrap>", line 994, in _gcd_import
  File "<frozen importlib._bootstrap>", line 971, in _find_and_load
  File "<frozen importlib._bootstrap>", line 955, in _find_and_load_unlocked
  File "<frozen importlib._bootstrap>", line 665, in _load_unlocked
  File "<frozen importlib._bootstrap_external>", line 678, in exec_module
  File "<frozen importlib._bootstrap>", line 219, in _call_with_frames_removed
  File "C:\Users\siddhant\Desktop\steps\django_steps\api\urls.py", line 2, in <module>
    from . import views
  File "C:\Users\siddhant\Desktop\steps\django_steps\api\views.py", line 4, in <module>
    from .serializers import SidewalkSerializer, SidewalkRatingsSerializer
  File "C:\Users\siddhant\Desktop\steps\django_steps\api\serializers.py", line 20
    def SidewalkCommentSerializer(serializers.ModelSerializer):
                                             ^
SyntaxError: invalid syntax
Performing system checks...

Unhandled exception in thread started by <function check_errors.<locals>.wrapper at 0x0359B0C0>
Traceback (most recent call last):
  File "C:\Users\siddhant\AppData\Local\Programs\Python\Python36-32\lib\site-packages\django\utils\autoreload.py", line 225, in wrapper
    fn(*args, **kwargs)
  File "C:\Users\siddhant\AppData\Local\Programs\Python\Python36-32\lib\site-packages\django\core\management\commands\runserver.py", line 117, in inner_run
    self.check(display_num_errors=True)
  File "C:\Users\siddhant\AppData\Local\Programs\Python\Python36-32\lib\site-packages\django\core\management\base.py", line 379, in check
    include_deployment_checks=include_deployment_checks,
  File "C:\Users\siddhant\AppData\Local\Programs\Python\Python36-32\lib\site-packages\django\core\management\base.py", line 366, in _run_checks
    return checks.run_checks(**kwargs)
  File "C:\Users\siddhant\AppData\Local\Programs\Python\Python36-32\lib\site-packages\django\core\checks\registry.py", line 71, in run_checks
    new_errors = check(app_configs=app_configs)
  File "C:\Users\siddhant\AppData\Local\Programs\Python\Python36-32\lib\site-packages\django\core\checks\urls.py", line 40, in check_url_namespaces_unique
    all_namespaces = _load_all_namespaces(resolver)
  File "C:\Users\siddhant\AppData\Local\Programs\Python\Python36-32\lib\site-packages\django\core\checks\urls.py", line 57, in _load_all_namespaces
    url_patterns = getattr(resolver, 'url_patterns', [])
  File "C:\Users\siddhant\AppData\Local\Programs\Python\Python36-32\lib\site-packages\django\utils\functional.py", line 37, in __get__
    res = instance.__dict__[self.name] = self.func(instance)
  File "C:\Users\siddhant\AppData\Local\Programs\Python\Python36-32\lib\site-packages\django\urls\resolvers.py", line 533, in url_patterns
    patterns = getattr(self.urlconf_module, "urlpatterns", self.urlconf_module)
  File "C:\Users\siddhant\AppData\Local\Programs\Python\Python36-32\lib\site-packages\django\utils\functional.py", line 37, in __get__
    res = instance.__dict__[self.name] = self.func(instance)
  File "C:\Users\siddhant\AppData\Local\Programs\Python\Python36-32\lib\site-packages\django\urls\resolvers.py", line 526, in urlconf_module
    return import_module(self.urlconf_name)
  File "C:\Users\siddhant\AppData\Local\Programs\Python\Python36-32\lib\importlib\__init__.py", line 126, in import_module
    return _bootstrap._gcd_import(name[level:], package, level)
  File "<frozen importlib._bootstrap>", line 994, in _gcd_import
  File "<frozen importlib._bootstrap>", line 971, in _find_and_load
  File "<frozen importlib._bootstrap>", line 955, in _find_and_load_unlocked
  File "<frozen importlib._bootstrap>", line 665, in _load_unlocked
  File "<frozen importlib._bootstrap_external>", line 678, in exec_module
  File "<frozen importlib._bootstrap>", line 219, in _call_with_frames_removed
  File "C:\Users\siddhant\Desktop\steps\django_steps\steps\urls.py", line 23, in <module>
    path('api/', include('api.urls')),
  File "C:\Users\siddhant\AppData\Local\Programs\Python\Python36-32\lib\site-packages\django\urls\conf.py", line 34, in include
    urlconf_module = import_module(urlconf_module)
  File "C:\Users\siddhant\AppData\Local\Programs\Python\Python36-32\lib\importlib\__init__.py", line 126, in import_module
    return _bootstrap._gcd_import(name[level:], package, level)
  File "<frozen importlib._bootstrap>", line 994, in _gcd_import
  File "<frozen importlib._bootstrap>", line 971, in _find_and_load
  File "<frozen importlib._bootstrap>", line 955, in _find_and_load_unlocked
  File "<frozen importlib._bootstrap>", line 665, in _load_unlocked
  File "<frozen importlib._bootstrap_external>", line 678, in exec_module
  File "<frozen importlib._bootstrap>", line 219, in _call_with_frames_removed
  File "C:\Users\siddhant\Desktop\steps\django_steps\api\urls.py", line 2, in <module>
    from . import views
  File "C:\Users\siddhant\Desktop\steps\django_steps\api\views.py", line 4, in <module>
    from .serializers import SidewalkSerializer, SidewalkRatingsSerializer
  File "C:\Users\siddhant\Desktop\steps\django_steps\api\serializers.py", line 20
    def SidewalkCommentSerializer(serializers.ModelSerializer):
                                             ^
SyntaxError: invalid syntax
Performing system checks...

Unhandled exception in thread started by <function check_errors.<locals>.wrapper at 0x0352B0C0>
Traceback (most recent call last):
  File "C:\Users\siddhant\AppData\Local\Programs\Python\Python36-32\lib\site-packages\django\utils\autoreload.py", line 225, in wrapper
    fn(*args, **kwargs)
  File "C:\Users\siddhant\AppData\Local\Programs\Python\Python36-32\lib\site-packages\django\core\management\commands\runserver.py", line 117, in inner_run
    self.check(display_num_errors=True)
  File "C:\Users\siddhant\AppData\Local\Programs\Python\Python36-32\lib\site-packages\django\core\management\base.py", line 379, in check
    include_deployment_checks=include_deployment_checks,
  File "C:\Users\siddhant\AppData\Local\Programs\Python\Python36-32\lib\site-packages\django\core\management\base.py", line 366, in _run_checks
    return checks.run_checks(**kwargs)
  File "C:\Users\siddhant\AppData\Local\Programs\Python\Python36-32\lib\site-packages\django\core\checks\registry.py", line 71, in run_checks
    new_errors = check(app_configs=app_configs)
  File "C:\Users\siddhant\AppData\Local\Programs\Python\Python36-32\lib\site-packages\django\core\checks\urls.py", line 40, in check_url_namespaces_unique
    all_namespaces = _load_all_namespaces(resolver)
  File "C:\Users\siddhant\AppData\Local\Programs\Python\Python36-32\lib\site-packages\django\core\checks\urls.py", line 57, in _load_all_namespaces
    url_patterns = getattr(resolver, 'url_patterns', [])
  File "C:\Users\siddhant\AppData\Local\Programs\Python\Python36-32\lib\site-packages\django\utils\functional.py", line 37, in __get__
    res = instance.__dict__[self.name] = self.func(instance)
  File "C:\Users\siddhant\AppData\Local\Programs\Python\Python36-32\lib\site-packages\django\urls\resolvers.py", line 533, in url_patterns
    patterns = getattr(self.urlconf_module, "urlpatterns", self.urlconf_module)
  File "C:\Users\siddhant\AppData\Local\Programs\Python\Python36-32\lib\site-packages\django\utils\functional.py", line 37, in __get__
    res = instance.__dict__[self.name] = self.func(instance)
  File "C:\Users\siddhant\AppData\Local\Programs\Python\Python36-32\lib\site-packages\django\urls\resolvers.py", line 526, in urlconf_module
    return import_module(self.urlconf_name)
  File "C:\Users\siddhant\AppData\Local\Programs\Python\Python36-32\lib\importlib\__init__.py", line 126, in import_module
    return _bootstrap._gcd_import(name[level:], package, level)
  File "<frozen importlib._bootstrap>", line 994, in _gcd_import
  File "<frozen importlib._bootstrap>", line 971, in _find_and_load
  File "<frozen importlib._bootstrap>", line 955, in _find_and_load_unlocked
  File "<frozen importlib._bootstrap>", line 665, in _load_unlocked
  File "<frozen importlib._bootstrap_external>", line 678, in exec_module
  File "<frozen importlib._bootstrap>", line 219, in _call_with_frames_removed
  File "C:\Users\siddhant\Desktop\steps\django_steps\steps\urls.py", line 23, in <module>
    path('api/', include('api.urls')),
  File "C:\Users\siddhant\AppData\Local\Programs\Python\Python36-32\lib\site-packages\django\urls\conf.py", line 34, in include
    urlconf_module = import_module(urlconf_module)
  File "C:\Users\siddhant\AppData\Local\Programs\Python\Python36-32\lib\importlib\__init__.py", line 126, in import_module
    return _bootstrap._gcd_import(name[level:], package, level)
  File "<frozen importlib._bootstrap>", line 994, in _gcd_import
  File "<frozen importlib._bootstrap>", line 971, in _find_and_load
  File "<frozen importlib._bootstrap>", line 955, in _find_and_load_unlocked
  File "<frozen importlib._bootstrap>", line 665, in _load_unlocked
  File "<frozen importlib._bootstrap_external>", line 678, in exec_module
  File "<frozen importlib._bootstrap>", line 219, in _call_with_frames_removed
  File "C:\Users\siddhant\Desktop\steps\django_steps\api\urls.py", line 2, in <module>
    from . import views
  File "C:\Users\siddhant\Desktop\steps\django_steps\api\views.py", line 4, in <module>
    from .serializers import SidewalkSerializer, SidewalkRatingsSerializer
  File "C:\Users\siddhant\Desktop\steps\django_steps\api\serializers.py", line 20
    def SidewalkCommentSerializer(serializers.ModelSerializer):
                                             ^
SyntaxError: invalid syntax
Performing system checks...

Performing system checks...

System check identified no issues (0 silenced).
October 20, 2018 - 16:58:10
Django version 2.1.1, using settings 'steps.settings'
Starting development server at http://0.0.0.0:8000/
Quit the server with CTRL-BREAK.
[20/Oct/2018 17:03:12] "GET /api/ HTTP/1.1" 200 5370
[20/Oct/2018 17:03:13] "GET /favicon.ico HTTP/1.1" 200 2116
Performing system checks...

System check identified no issues (0 silenced).
October 20, 2018 - 17:02:45
Django version 2.1.1, using settings 'steps.settings'
Starting development server at http://0.0.0.0:8000/
Quit the server with CTRL-BREAK.
Performing system checks...

System check identified no issues (0 silenced).
October 20, 2018 - 17:04:14
Django version 2.1.1, using settings 'steps.settings'
Starting development server at http://0.0.0.0:8000/
Quit the server with CTRL-BREAK.
[20/Oct/2018 17:04:42] "GET /api/ HTTP/1.1" 200 5370
[20/Oct/2018 17:04:43] "GET /favicon.ico HTTP/1.1" 200 2116
Performing system checks...

System check identified no issues (0 silenced).
October 20, 2018 - 17:04:22
Django version 2.1.1, using settings 'steps.settings'
Starting development server at http://0.0.0.0:8000/
Quit the server with CTRL-BREAK.
[20/Oct/2018 17:07:07] "GET /api/ HTTP/1.1" 200 5984
[20/Oct/2018 17:07:09] "GET /favicon.ico HTTP/1.1" 200 2116
[20/Oct/2018 17:07:10] "GET /api/pedestrian/ HTTP/1.1" 200 4968
[20/Oct/2018 17:07:11] "GET /favicon.ico HTTP/1.1" 200 2116
[20/Oct/2018 17:07:12] "GET /favicon.ico HTTP/1.1" 200 2116
[20/Oct/2018 17:07:13] "GET /api/sidewalkComment/ HTTP/1.1" 200 5029
[20/Oct/2018 17:07:14] "GET /favicon.ico HTTP/1.1" 200 2116
[20/Oct/2018 17:07:14] "GET /favicon.ico HTTP/1.1" 200 2116
[20/Oct/2018 17:07:15] "GET /api/sidewalkRating/ HTTP/1.1" 200 5419
[20/Oct/2018 17:07:16] "GET /favicon.ico HTTP/1.1" 200 2116
[20/Oct/2018 17:07:18] "GET /favicon.ico HTTP/1.1" 200 2116
[20/Oct/2018 17:07:18] "GET /api/sidewalk/ HTTP/1.1" 200 4985
[20/Oct/2018 17:07:19] "GET /favicon.ico HTTP/1.1" 200 2116
[20/Oct/2018 17:07:20] "GET /favicon.ico HTTP/1.1" 200 2116
[20/Oct/2018 17:07:22] "GET /favicon.ico HTTP/1.1" 200 2116
Performing system checks...

System check identified no issues (0 silenced).
October 20, 2018 - 17:07:05
Django version 2.1.1, using settings 'steps.settings'
Starting development server at http://0.0.0.0:8000/
Quit the server with CTRL-BREAK.
